Workbook
Name Desc_Categoria: 'Cadastros Auxiliares'!$B$8:$E$8
Name Desc_Qtde: 'Cadastros Auxiliares'!$B$8:$B$13
Name Desc_Tabela: 'Cadastros Auxiliares'!$B$8:$E$13
Name Desc_TabelaTotal: 'Cadastros Auxiliares'!$B$8:$E$13
Name Int_Nome_Produtos: #REF!
Name Int_Quantidade: #REF!
Name SegmentaçãodeDados_Data__Ano: #N/A
Name SegmentaçãodeDados_Mês: #N/A
Name Vendas_Historico: Vendas[#All]

Sheet Menu

Sheet Dashboard 
C9: Vendas Mensais
C26: Vendas por Categoria | AQ26: Ranking Vendedores

Sheet Produtos
B1: Controle de Produtos
B6: Código | C6: Produtos | D6: Tamanho | E6: Categoria | F6: Estoque | G6: Preço Unitário
B7: PR001 | C7: Bermuda | D7: P | E7: Vestuário | F7: 0 | G7: 65.9
B8: PR002 | C8: Bermuda | D8: M | E8: Vestuário | F8: 10 | G8: 69.9
B9: PR003 | C9: Bermuda | D9: G | E9: Vestuário | F9: 37 | G9: 70.9
B10: PR004 | C10: Bolsa coringa | D10: Único | E10: Acessórios | F10: 5 | G10: 145
B11: PR005 | C11: Bolsa de couro | D11: Único | E11: Acessórios | F11: 21 | G11: 259.9
B12: PR006 | C12: Boné | D12: Único | E12: Acessórios | F12: 23 | G12: 39.9
B13: PR007 | C13: Calça jeans | D13: P | E13: Vestuário | F13: 24 | G13: 85.9
B14: PR008 | C14: Calça jeans | D14: M | E14: Vestuário | F14: 35 | G14: 89.9
B15: PR009 | C15: Calça jeans | D15: G | E15: Vestuário | F15: 47 | G15: 92.9
B16: PR010 | C16: Calça legging | D16: P | E16: Vestuário | F16: 42 | G16: 44.9
B17: PR011 | C17: Calça legging | D17: M | E17: Vestuário | F17: 32 | G17: 46.9
B18: PR012 | C18: Calça legging | D18: G | E18: Vestuário | F18: 45 | G18: 48.9
... B33: PR027 | C33: Óculos redondo | D33: Único | E33: Acessórios | F33: 45 | G33: 120
B34: PR028 | C34: Tênis Atitas | D34: 36 | E34: Calçado | F34: 37 | G34: 249.9
B35: PR029 | C35: Tênis Atitas | D35: 37 | E35: Calçado | F35: 41 | G35: 255
B36: PR030 | C36: Tênis Atitas | D36: 38 | E36: Calçado | F36: 30 | G36: 259.9
B37: PR031 | C37: Tênis Chunky | D37: 36 | E37: Calçado | F37: 27 | G37: 245
B38: PR032 | C38: Tênis Chunky | D38: 37 | E38: Calçado | F38: 41 | G38: 250
B39: PR033 | C39: Tênis Chunky | D39: 38 | E39: Calçado | F39: 43 | G39: 259.9
B40: PR034 | C40: Vestido curto | D40: P | E40: Vestuário | F40: 43 | G40: 89.9
B41: PR035 | C41: Vestido curto | D41: M | E41: Vestuário | F41: 18 | G41: 91.4
B42: PR036 | C42: Vestido curto | D42: G | E42: Vestuário | F42: 45 | G42: 93.5
B43: PR037 | C43: Vestido longo | D43: P | E43: Vestuário | F43: 34 | G43: 140
B44: PR038 | C44: Vestido longo | D44: M | E44: Vestuário | F44: 47 | G44: 142.9
B45: PR039 | C45: Vestido longo | D45: G | E45: Vestuário | F45: 50 | G45: 146
B46: PR040 | C46: Camiseta Conforto | D46: P | E46: Vestuário | F46: 16 | G46: 70
B47: PR041 | C47: Camiseta Conforto | D47: M | E47: Vestuário | F47: 21 | G47: 54.9
B48: PR042 | C48: Camiseta Conforto | D48: G | E48: Vestuário | F48: 43 | G48: 54.9
B49: PR043 | C49: Vestido Floral | D49: P | E49: Vestuário | F49: 43 | G49: 72.5
B50: PR044 | C50: Vestido Floral | D50: M | E50: Vestuário | F50: 41 | G50: 72.5
B51: PR045 | C51: Vestido Floral | D51: G | E51: Vestuário | F51: 49 | G51: 72.5
... B60: PR054 | C60: Saia Plissada | D60: G | E60: Vestuário | F60: 18 | G60: 49.9
B61: PR055 | C61: Sandália Rasteira | D61: 35 | E61: Calçado | F61: 48 | G61: 89.9
B62: PR056 | C62: Sandália Rasteira | D62: 36 | E62: Calçado | F62: 38 | G62: 89.9
B63: PR057 | C63: Sandália Rasteira | D63: 37 | E63: Calçado | F63: 45 | G63: 89.9
B64: PR058 | C64: Calça Alfaiataria | D64: P | E64: Vestuário | F64: 40 | G64: 180
B65: PR059 | C65: Calça Alfaiataria | D65: M | E65: Vestuário | F65: 35 | G65: 180
B66: PR060 | C66: Calça Alfaiataria | D66: G | E66: Vestuário | F66: 35 | G66: 180
...

Sheet Vendedores
B1: Controle de Produtos
A4: Código | B4: Vendedor | C4: Cidade | D4: Desc. Máximo
A5: VD001 | B5: João | C5: São Paulo | D5: 0.2
A6: VD002 | B6: Sarah | C6: Rio de Janeiro | D6: 0.25
A7: VD003 | B7: Clara | C7: Natal | D7: 0.1
A8: VD004 | B8: Amanda | C8: Manaus | D8: 0.2
A9: VD005 | B9: Bruno | C9: Belo Horizonte | D9: 0.15

Sheet Vendas
B1: Vendas
A4: Nº | B4: Data | C4: Código | D4: Categoria | E4: Qtd | F4: Preço Unitário | G4: Índice | H4: Desc_Simples | I4: Desc_Direto | J4: Desc_Vendedor | K4: Desc_Real | L4: Total | M4: Vendedor
A5: =MONTH(TB_Vendas[[#This Row],[Data]]) -> 1 | B5: 44931 | C5: PR006 | D5: {=_xlfn.XLOOKUP(TB_Vendas[[#This Row],[Código]],TB_Produtos[[#All],[Código]],TB_Produtos[[#All],[Categoria]])} -> Acessórios | E5: 1 | F5: =VLOOKUP(TB_Vendas[[#This Row],[Código]],TB_Produtos[#All],6,FALSE) -> 39.9 | G5: =_xlfn.XMATCH(TB_Vendas[[#This Row],[Categoria]],Desc_Categoria) -> 2 | H5: =VLOOKUP(TB_Vendas[[#This Row],[Qtd]],Desc_Tabela,TB_Vendas[[#This Row],[Índice]]) -> 0 | I5: {=INDEX(Desc_TabelaTotal,MATCH(TB_Vendas[[#This Row],[Qtd]],Desc_Qtde,1),MATCH(_xlfn.XLOOKUP(C5,TB_Produtos[[#All],[Código]],TB_Produtos[[#All],[Categoria]]),Desc_Categoria,0))} -> 0 | J5: =_xlfn.XLOOKUP(TB_Vendas[[#This Row],[Vendedor]],Vendedores!$A$4:$A$9,Vendedores!$D$5:$D$10) -> 0.1 | K5: =IF(TB_Vendas[[#This Row],[Desc_Direto]]>TB_Vendas[[#This Row],[Desc_Vendedor]],TB_Vendas[[#This Row],[Desc_Vendedor]],TB_Vendas[[#This Row],[Desc_Direto]]) -> 0 | L5: =TB_Vendas[[#This Row],[Preço Unitário]]*TB_Vendas[[#This Row],[Qtd]] -> 39.9 | M5: VD002
A6: =MONTH(TB_Vendas[[#This Row],[Data]]) -> 1 | B6: 44932 | C6: PR005 | D6: {=_xlfn.XLOOKUP(TB_Vendas[[#This Row],[Código]],TB_Produtos[[#All],[Código]],TB_Produtos[[#All],[Categoria]])} -> Acessórios | E6: 1 | F6: =VLOOKUP(TB_Vendas[[#This Row],[Código]],TB_Produtos[#All],6,FALSE) -> 259.9 | G6: =_xlfn.XMATCH(TB_Vendas[[#This Row],[Categoria]],Desc_Categoria) -> 2 | H6: =VLOOKUP(TB_Vendas[[#This Row],[Qtd]],Desc_Tabela,TB_Vendas[[#This Row],[Índice]]) -> 0 | I6: {=INDEX(Desc_TabelaTotal,MATCH(TB_Vendas[[#This Row],[Qtd]],Desc_Qtde,1),MATCH(_xlfn.XLOOKUP(C6,TB_Produtos[[#All],[Código]],TB_Produtos[[#All],[Categoria]]),Desc_Categoria,0))} -> 0 | J6: =_xlfn.XLOOKUP(TB_Vendas[[#This Row],[Vendedor]],Vendedores!$A$4:$A$9,Vendedores!$D$5:$D$10) -> 0.1 | K6: =IF(TB_Vendas[[#This Row],[Desc_Direto]]>TB_Vendas[[#This Row],[Desc_Vendedor]],TB_Vendas[[#This Row],[Desc_Vendedor]],TB_Vendas[[#This Row],[Desc_Direto]]) -> 0 | L6: =TB_Vendas[[#This Row],[Preço Unitário]]*TB_Vendas[[#This Row],[Qtd]] -> 259.9 | M6: VD002
A7: =MONTH(TB_Vendas[[#This Row],[Data]]) -> 1 | B7: 44933 | C7: PR051 | D7: {=_xlfn.XLOOKUP(TB_Vendas[[#This Row],[Código]],TB_Produtos[[#All],[Código]],TB_Produtos[[#All],[Categoria]])} -> Vestuário | E7: 2 | F7: =VLOOKUP(TB_Vendas[[#This Row],[Código]],TB_Produtos[#All],6,FALSE) -> 32.9 | G7: =_xlfn.XMATCH(TB_Vendas[[#This Row],[Categoria]],Desc_Categoria) -> 3 | H7: =VLOOKUP(TB_Vendas[[#This Row],[Qtd]],Desc_Tabela,TB_Vendas[[#This Row],[Índice]]) -> 0.15 | I7: {=INDEX(Desc_TabelaTotal,MATCH(TB_Vendas[[#This Row],[Qtd]],Desc_Qtde,1),MATCH(_xlfn.XLOOKUP(C7,TB_Produtos[[#All],[Código]],TB_Produtos[[#All],[Categoria]]),Desc_Categoria,0))} -> 0.15 | J7: =_xlfn.XLOOKUP(TB_Vendas[[#This Row],[Vendedor]],Vendedores!$A$4:$A$9,Vendedores!$D$5:$D$10) -> 0.25 | K7: =IF(TB_Vendas[[#This Row],[Desc_Direto]]>TB_Vendas[[#This Row],[Desc_Vendedor]],TB_Vendas[[#This Row],[Desc_Vendedor]],TB_Vendas[[#This Row],[Desc_Direto]]) -> 0.15 | L7: =TB_Vendas[[#This Row],[Preço Unitário]]*TB_Vendas[[#This Row],[Qtd]] -> 65.8 | M7: VD001
A8: =MONTH(TB_Vendas[[#This Row],[Data]]) -> 1 | B8: 44938 | C8: PR011 | D8: {=_xlfn.XLOOKUP(TB_Vendas[[#This Row],[Código]],TB_Produtos[[#All],[Código]],TB_Produtos[[#All],[Categoria]])} -> Vestuário | E8: 1 | F8: =VLOOKUP(TB_Vendas[[#This Row],[Código]],TB_Produtos[#All],6,FALSE) -> 46.9 | G8: =_xlfn.XMATCH(TB_Vendas[[#This Row],[Categoria]],Desc_Categoria) -> 3 | H8: =VLOOKUP(TB_Vendas[[#This Row],[Qtd]],Desc_Tabela,TB_Vendas[[#This Row],[Índice]]) -> 0.1 | I8: {=INDEX(Desc_TabelaTotal,MATCH(TB_Vendas[[#This Row],[Qtd]],Desc_Qtde,1),MATCH(_xlfn.XLOOKUP(C8,TB_Produtos[[#All],[Código]],TB_Produtos[[#All],[Categoria]]),Desc_Categoria,0))} -> 0.1 | J8: =_xlfn.XLOOKUP(TB_Vendas[[#This Row],[Vendedor]],Vendedores!$A$4:$A$9,Vendedores!$D$5:$D$10) -> 0 | K8: =IF(TB_Vendas[[#This Row],[Desc_Direto]]>TB_Vendas[[#This Row],[Desc_Vendedor]],TB_Vendas[[#This Row],[Desc_Vendedor]],TB_Vendas[[#This Row],[Desc_Direto]]) -> 0 | L8: =TB_Vendas[[#This Row],[Preço Unitário]]*TB_Vendas[[#This Row],[Qtd]] -> 46.9 | M8: VD005
A9: =MONTH(TB_Vendas[[#This Row],[Data]]) -> 1 | B9: 44939 | C9: PR017 | D9: {=_xlfn.XLOOKUP(TB_Vendas[[#This Row],[Código]],TB_Produtos[[#All],[Código]],TB_Produtos[[#All],[Categoria]])} -> Vestuário | E9: 1 | F9: =VLOOKUP(TB_Vendas[[#This Row],[Código]],TB_Produtos[#All],6,FALSE) -> 29.9 | G9: =_xlfn.XMATCH(TB_Vendas[[#This Row],[Categoria]],Desc_Categoria) -> 3 | H9: =VLOOKUP(TB_Vendas[[#This Row],[Qtd]],Desc_Tabela,TB_Vendas[[#This Row],[Índice]]) -> 0.1 | I9: {=INDEX(Desc_TabelaTotal,MATCH(TB_Vendas[[#This Row],[Qtd]],Desc_Qtde,1),MATCH(_xlfn.XLOOKUP(C9,TB_Produtos[[#All],[Código]],TB_Produtos[[#All],[Categoria]]),Desc_Categoria,0))} -> 0.1 | J9: =_xlfn.XLOOKUP(TB_Vendas[[#This Row],[Vendedor]],Vendedores!$A$4:$A$9,Vendedores!$D$5:$D$10) -> 0.1 | K9: =IF(TB_Vendas[[#This Row],[Desc_Direto]]>TB_Vendas[[#This Row],[Desc_Vendedor]],TB_Vendas[[#This Row],[Desc_Vendedor]],TB_Vendas[[#This Row],[Desc_Direto]]) -> 0.1 | L9: =TB_Vendas[[#This Row],[Preço Unitário]]*TB_Vendas[[#This Row],[Qtd]] -> 29.9 | M9: VD002
A10: =MONTH(TB_Vendas[[#This Row],[Data]]) -> 1 | B10: 44943 | C10: PR025 | D10: {=_xlfn.XLOOKUP(TB_Vendas[[#This Row],[Código]],TB_Produtos[[#All],[Código]],TB_Produtos[[#All],[Categoria]])} -> Vestuário | E10: 1 | F10: =VLOOKUP(TB_Vendas[[#This Row],[Código]],TB_Produtos[#All],6,FALSE) -> 299.9 | G10: =_xlfn.XMATCH(TB_Vendas[[#This Row],[Categoria]],Desc_Categoria) -> 3 | H10: =VLOOKUP(TB_Vendas[[#This Row],[Qtd]],Desc_Tabela,TB_Vendas[[#This Row],[Índice]]) -> 0.1 | I10: {=INDEX(Desc_TabelaTotal,MATCH(TB_Vendas[[#This Row],[Qtd]],Desc_Qtde,1),MATCH(_xlfn.XLOOKUP(C10,TB_Produtos[[#All],[Código]],TB_Produtos[[#All],[Categoria]]),Desc_Categoria,0))} -> 0.1 | J10: =_xlfn.XLOOKUP(TB_Vendas[[#This Row],[Vendedor]],Vendedores!$A$4:$A$9,Vendedores!$D$5:$D$10) -> 0 | K10: =IF(TB_Vendas[[#This Row],[Desc_Direto]]>TB_Vendas[[#This Row],[Desc_Vendedor]],TB_Vendas[[#This Row],[Desc_Vendedor]],TB_Vendas[[#This Row],[Desc_Direto]]) -> 0 | L10: =TB_Vendas[[#This Row],[Preço Unitário]]*TB_Vendas[[#This Row],[Qtd]] -> 299.9 | M10: VD005
A11: =MONTH(TB_Vendas[[#This Row],[Data]]) -> 1 | B11: 44949 | C11: PR039 | D11: {=_xlfn.XLOOKUP(TB_Vendas[[#This Row],[Código]],TB_Produtos[[#All],[Código]],TB_Produtos[[#All],[Categoria]])} -> Vestuário | E11: 1 | F11: =VLOOKUP(TB_Vendas[[#This Row],[Código]],TB_Produtos[#All],6,FALSE) -> 146 | G11: =_xlfn.XMATCH(TB_Vendas[[#This Row],[Categoria]],Desc_Categoria) -> 3 | H11: =VLOOKUP(TB_Vendas[[#This Row],[Qtd]],Desc_Tabela,TB_Vendas[[#This Row],[Índice]]) -> 0.1 | I11: {=INDEX(Desc_TabelaTotal,MATCH(TB_Vendas[[#This Row],[Qtd]],Desc_Qtde,1),MATCH(_xlfn.XLOOKUP(C11,TB_Produtos[[#All],[Código]],TB_Produtos[[#All],[Categoria]]),Desc_Categoria,0))} -> 0.1 | J11: =_xlfn.XLOOKUP(TB_Vendas[[#This Row],[Vendedor]],Vendedores!$A$4:$A$9,Vendedores!$D$5:$D$10) -> 0.2 | K11: =IF(TB_Vendas[[#This Row],[Desc_Direto]]>TB_Vendas[[#This Row],[Desc_Vendedor]],TB_Vendas[[#This Row],[Desc_Vendedor]],TB_Vendas[[#This Row],[Desc_Direto]]) -> 0.1 | L11: =TB_Vendas[[#This Row],[Preço Unitário]]*TB_Vendas[[#This Row],[Qtd]] -> 146 | M11: VD003
A12: =MONTH(TB_Vendas[[#This Row],[Data]]) -> 1 | B12: 44952 | C12: PR034 | D12: {=_xlfn.XLOOKUP(TB_Vendas[[#This Row],[Código]],TB_Produtos[[#All],[Código]],TB_Produtos[[#All],[Categoria]])} -> Vestuário | E12: 2 | F12: =VLOOKUP(TB_Vendas[[#This Row],[Código]],TB_Produtos[#All],6,FALSE) -> 89.9 | G12: =_xlfn.XMATCH(TB_Vendas[[#This Row],[Categoria]],Desc_Categoria) -> 3 | H12: =VLOOKUP(TB_Vendas[[#This Row],[Qtd]],Desc_Tabela,TB_Vendas[[#This Row],[Índice]]) -> 0.15 | I12: {=INDEX(Desc_TabelaTotal,MATCH(TB_Vendas[[#This Row],[Qtd]],Desc_Qtde,1),MATCH(_xlfn.XLOOKUP(C12,TB_Produtos[[#All],[Código]],TB_Produtos[[#All],[Categoria]]),Desc_Categoria,0))} -> 0.15 | J12: =_xlfn.XLOOKUP(TB_Vendas[[#This Row],[Vendedor]],Vendedores!$A$4:$A$9,Vendedores!$D$5:$D$10) -> 0.2 | K12: =IF(TB_Vendas[[#This Row],[Desc_Direto]]>TB_Vendas[[#This Row],[Desc_Vendedor]],TB_Vendas[[#This Row],[Desc_Vendedor]],TB_Vendas[[#This Row],[Desc_Direto]]) -> 0.15 | L12: =TB_Vendas[[#This Row],[Preço Unitário]]*TB_Vendas[[#This Row],[Qtd]] -> 179.8 | M12: VD003
A13: =MONTH(TB_Vendas[[#This Row],[Data]]) -> 1 | B13: 44954 | C13: PR032 | D13: {=_xlfn.XLOOKUP(TB_Vendas[[#This Row],[Código]],TB_Produtos[[#All],[Código]],TB_Produtos[[#All],[Categoria]])} -> Calçado | E13: 2 | F13: =VLOOKUP(TB_Vendas[[#This Row],[Código]],TB_Produtos[#All],6,FALSE) -> 250 | G13: =_xlfn.XMATCH(TB_Vendas[[#This Row],[Categoria]],Desc_Categoria) -> 4 | H13: =VLOOKUP(TB_Vendas[[#This Row],[Qtd]],Desc_Tabela,TB_Vendas[[#This Row],[Índice]]) -> 0.1 | I13: {=INDEX(Desc_TabelaTotal,MATCH(TB_Vendas[[#This Row],[Qtd]],Desc_Qtde,1),MATCH(_xlfn.XLOOKUP(C13,TB_Produtos[[#All],[Código]],TB_Produtos[[#All],[Categoria]]),Desc_Categoria,0))} -> 0.1 | J13: =_xlfn.XLOOKUP(TB_Vendas[[#This Row],[Vendedor]],Vendedores!$A$4:$A$9,Vendedores!$D$5:$D$10) -> 0.1 | K13: =IF(TB_Vendas[[#This Row],[Desc_Direto]]>TB_Vendas[[#This Row],[Desc_Vendedor]],TB_Vendas[[#This Row],[Desc_Vendedor]],TB_Vendas[[#This Row],[Desc_Direto]]) -> 0.1 | L13: =TB_Vendas[[#This Row],[Preço Unitário]]*TB_Vendas[[#This Row],[Qtd]] -> 500 | M13: VD002
A14: =MONTH(TB_Vendas[[#This Row],[Data]]) -> 1 | B14: 44955 | C14: PR013 | D14: {=_xlfn.XLOOKUP(TB_Vendas[[#This Row],[Código]],TB_Produtos[[#All],[Código]],TB_Produtos[[#All],[Categoria]])} -> Vestuário | E14: 1 | F14: =VLOOKUP(TB_Vendas[[#This Row],[Código]],TB_Produtos[#All],6,FALSE) -> 39.9 | G14: =_xlfn.XMATCH(TB_Vendas[[#This Row],[Categoria]],Desc_Categoria) -> 3 | H14: =VLOOKUP(TB_Vendas[[#This Row],[Qtd]],Desc_Tabela,TB_Vendas[[#This Row],[Índice]]) -> 0.1 | I14: {=INDEX(Desc_TabelaTotal,MATCH(TB_Vendas[[#This Row],[Qtd]],Desc_Qtde,1),MATCH(_xlfn.XLOOKUP(C14,TB_Produtos[[#All],[Código]],TB_Produtos[[#All],[Categoria]]),Desc_Categoria,0))} -> 0.1 | J14: =_xlfn.XLOOKUP(TB_Vendas[[#This Row],[Vendedor]],Vendedores!$A$4:$A$9,Vendedores!$D$5:$D$10) -> 0.1 | K14: =IF(TB_Vendas[[#This Row],[Desc_Direto]]>TB_Vendas[[#This Row],[Desc_Vendedor]],TB_Vendas[[#This Row],[Desc_Vendedor]],TB_Vendas[[#This Row],[Desc_Direto]]) -> 0.1 | L14: =TB_Vendas[[#This Row],[Preço Unitário]]*TB_Vendas[[#This Row],[Qtd]] -> 39.9 | M14: VD002
A15: =MONTH(TB_Vendas[[#This Row],[Data]]) -> 1 | B15: 44956 | C15: PR038 | D15: {=_xlfn.XLOOKUP(TB_Vendas[[#This Row],[Código]],TB_Produtos[[#All],[Código]],TB_Produtos[[#All],[Categoria]])} -> Vestuário | E15: 1 | F15: =VLOOKUP(TB_Vendas[[#This Row],[Código]],TB_Produtos[#All],6,FALSE) -> 142.9 | G15: =_xlfn.XMATCH(TB_Vendas[[#This Row],[Categoria]],Desc_Categoria) -> 3 | H15: =VLOOKUP(TB_Vendas[[#This Row],[Qtd]],Desc_Tabela,TB_Vendas[[#This Row],[Índice]]) -> 0.1 | I15: {=INDEX(Desc_TabelaTotal,MATCH(TB_Vendas[[#This Row],[Qtd]],Desc_Qtde,1),MATCH(_xlfn.XLOOKUP(C15,TB_Produtos[[#All],[Código]],TB_Produtos[[#All],[Categoria]]),Desc_Categoria,0))} -> 0.1 | J15: =_xlfn.XLOOKUP(TB_Vendas[[#This Row],[Vendedor]],Vendedores!$A$4:$A$9,Vendedores!$D$5:$D$10) -> 0.15 | K15: =IF(TB_Vendas[[#This Row],[Desc_Direto]]>TB_Vendas[[#This Row],[Desc_Vendedor]],TB_Vendas[[#This Row],[Desc_Vendedor]],TB_Vendas[[#This Row],[Desc_Direto]]) -> 0.1 | L15: =TB_Vendas[[#This Row],[Preço Unitário]]*TB_Vendas[[#This Row],[Qtd]] -> 142.9 | M15: VD004
A16: =MONTH(TB_Vendas[[#This Row],[Data]]) -> 2 | B16: 44960 | C16: PR022 | D16: {=_xlfn.XLOOKUP(TB_Vendas[[#This Row],[Código]],TB_Produtos[[#All],[Código]],TB_Produtos[[#All],[Categoria]])} -> Vestuário | E16: 1 | F16: =VLOOKUP(TB_Vendas[[#This Row],[Código]],TB_Produtos[#All],6,FALSE) -> 300 | G16: =_xlfn.XMATCH(TB_Vendas[[#This Row],[Categoria]],Desc_Categoria) -> 3 | H16: =VLOOKUP(TB_Vendas[[#This Row],[Qtd]],Desc_Tabela,TB_Vendas[[#This Row],[Índice]]) -> 0.1 | I16: {=INDEX(Desc_TabelaTotal,MATCH(TB_Vendas[[#This Row],[Qtd]],Desc_Qtde,1),MATCH(_xlfn.XLOOKUP(C16,TB_Produtos[[#All],[Código]],TB_Produtos[[#All],[Categoria]]),Desc_Categoria,0))} -> 0.1 | J16: =_xlfn.XLOOKUP(TB_Vendas[[#This Row],[Vendedor]],Vendedores!$A$4:$A$9,Vendedores!$D$5:$D$10) -> 0.2 | K16: =IF(TB_Vendas[[#This Row],[Desc_Direto]]>TB_Vendas[[#This Row],[Desc_Vendedor]],TB_Vendas[[#This Row],[Desc_Vendedor]],TB_Vendas[[#This Row],[Desc_Direto]]) -> 0.1 | L16: =TB_Vendas[[#This Row],[Preço Unitário]]*TB_Vendas[[#This Row],[Qtd]] -> 300 | M16: VD003
... A86: =MONTH(TB_Vendas[[#This Row],[Data]]) -> 8 | B86: 45153 | C86: PR014 | D86: {=_xlfn.XLOOKUP(TB_Vendas[[#This Row],[Código]],TB_Produtos[[#All],[Código]],TB_Produtos[[#All],[Categoria]])} -> Vestuário | E86: 8 | F86: =VLOOKUP(TB_Vendas[[#This Row],[Código]],TB_Produtos[#All],6,FALSE) -> 39.9 | G86: =_xlfn.XMATCH(TB_Vendas[[#This Row],[Categoria]],Desc_Categoria) -> 3 | H86: =VLOOKUP(TB_Vendas[[#This Row],[Qtd]],Desc_Tabela,TB_Vendas[[#This Row],[Índice]]) -> 0.25 | I86: {=INDEX(Desc_TabelaTotal,MATCH(TB_Vendas[[#This Row],[Qtd]],Desc_Qtde,1),MATCH(_xlfn.XLOOKUP(C86,TB_Produtos[[#All],[Código]],TB_Produtos[[#All],[Categoria]]),Desc_Categoria,0))} -> 0.25 | J86: =_xlfn.XLOOKUP(TB_Vendas[[#This Row],[Vendedor]],Vendedores!$A$4:$A$9,Vendedores!$D$5:$D$10) -> 0.1 | K86: =IF(TB_Vendas[[#This Row],[Desc_Direto]]>TB_Vendas[[#This Row],[Desc_Vendedor]],TB_Vendas[[#This Row],[Desc_Vendedor]],TB_Vendas[[#This Row],[Desc_Direto]]) -> 0.1 | L86: =TB_Vendas[[#This Row],[Preço Unitário]]*TB_Vendas[[#This Row],[Qtd]] -> 319.2 | M86: VD002

Sheet Cadastros Auxiliares
B1: Cadastros Gerais
B4: Código | C4: 1 | D4: 2 | E4: 3 | F4: 4 | G4: 5 | H4: 6 | I4: 7
B5: Dia da Semana | C5: Domingo | D5: Segunda-feira | E5: Terça-feira | F5: Quarta-feira | G5: Quinta-feira | H5: Sexta-feira | I5: Sábado
B8: Desconto por Categoria e Qtd | C8: Acessórios | D8: Vestuário | E8: Calçado | G8: Categoria | H8: Estoque mínimo
B9: 1 | C9: 0 | D9: 0.1 | E9: 0 | G9: Acessórios | H9: 5
B10: 2 | C10: 0.05 | D10: 0.15 | E10: 0.1 | G10: Vestuário | H10: 10
B11: 3 | C11: 0.15 | D11: 0.2 | E11: 0.15 | G11: Calçado | H11: 15
B12: 5 | C12: 0.25 | D12: 0.25 | E12: 0.25
B13: 10 | C13: 0.3 | D13: 0.3 | E13: 0.3

Sheet Vendas Histórico
A1: Mês | B1: Coluna1 | C1: Data | D1: Código | E1: Categoria | F1: Qtd | G1: Preço Unitário | H1: Desconto Final | I1: Total | J1: Vendedor
A2: Jan | B2: =MONTH(Vendas[[#This Row],[Data]]) -> 1 | C2: 44566 | D2: PR031 | E2: Calçado | F2: 2 | G2: 245 | H2: 0.1 | I2: 490 | J2: VD004
A3: Jan | B3: =MONTH(Vendas[[#This Row],[Data]]) -> 1 | C3: 44567 | D3: PR029 | E3: Calçado | F3: 10 | G3: 255 | H3: 0.15 | I3: 2550 | J3: VD005
A4: Jan | B4: =MONTH(Vendas[[#This Row],[Data]]) -> 1 | C4: 44568 | D4: PR048 | E4: Vestuário | F4: 11 | G4: 289.9 | H4: 0.1 | I4: 3188.9 | J4: VD003
A5: Jan | B5: =MONTH(Vendas[[#This Row],[Data]]) -> 1 | C5: 44573 | D5: PR058 | E5: Vestuário | F5: 11 | G5: 180 | H5: 0.2 | I5: 1980 | J5: VD001
A6: Jan | B6: =MONTH(Vendas[[#This Row],[Data]]) -> 1 | C6: 44574 | D6: PR060 | E6: Vestuário | F6: 10 | G6: 180 | H6: 0.1 | I6: 1800 | J6: VD003
A7: Jan | B7: =MONTH(Vendas[[#This Row],[Data]]) -> 1 | C7: 44578 | D7: PR003 | E7: Vestuário | F7: 8 | G7: 70.9 | H7: 0.15 | I7: 567.2 | J7: VD002
A8: Jan | B8: =MONTH(Vendas[[#This Row],[Data]]) -> 1 | C8: 44584 | D8: PR029 | E8: Calçado | F8: 2 | G8: 255 | H8: 0.1 | I8: 510 | J8: VD004
A9: Jan | B9: =MONTH(Vendas[[#This Row],[Data]]) -> 1 | C9: 44587 | D9: PR044 | E9: Vestuário | F9: 2 | G9: 72.5 | H9: 0.15 | I9: 145 | J9: VD005
A10: Jan | B10: =MONTH(Vendas[[#This Row],[Data]]) -> 1 | C10: 44589 | D10: PR046 | E10: Vestuário | F10: 12 | G10: 289.9 | H10: 0.2 | I10: 3478.8 | J10: VD004
A11: Jan | B11: =MONTH(Vendas[[#This Row],[Data]]) -> 1 | C11: 44590 | D11: PR046 | E11: Vestuário | F11: 1 | G11: 289.9 | H11: 0.1 | I11: 289.9 | J11: VD005
A12: Jan | B12: =MONTH(Vendas[[#This Row],[Data]]) -> 1 | C12: 44591 | D12: PR059 | E12: Vestuário | F12: 11 | G12: 180 | H12: 0.2 | I12: 1980 | J12: VD001
A13: Fev | B13: =MONTH(Vendas[[#This Row],[Data]]) -> 2 | C13: 44595 | D13: PR003 | E13: Vestuário | F13: 2 | G13: 70.9 | H13: 0.15 | I13: 141.8 | J13: VD001
... A253: Dez | B253: =MONTH(Vendas[[#This Row],[Data]]) -> 12 | C253: 44545 | D253: PR046 | E253: Vestuário | F253: 8 | G253: 289.9 | H253: 0.2 | I253: 2319.2 | J253: VD004

Sheet TBDN_Vendas Histórico
A2: Rótulos de Linha | B2: Soma de Total | C2: Soma Qtd
A3: Jan | B3: 27065.5 | C3: 154
A4: Fev | B4: 7502.6 | C4: 83
A5: Mar | B5: 7197.4 | C5: 114
A6: Abr | B6: 17379.8 | C6: 146
A7: Mai | B7: 20685.5 | C7: 114
A8: Jun | B8: 22586.3 | C8: 185
A9: Jul | B9: 18730.1 | C9: 133
A10: Ago | B10: 21585.8 | C10: 147
A11: Set | B11: 19851 | C11: 151
A12: Out | B12: 15659.4 | C12: 151
A13: Nov | B13: 9455.2 | C13: 92
A14: Dez | B14: 19742.5 | C14: 129
A15: Total Geral | B15: 207441.1 | C15: 1599
A21: Rótulos de Linha | B21: Soma de Total
A22: Clara | B22: 36204.6
A23: João | B23: 36468.6
A24: Amanda | B24: 37864
A25: Sarah | B25: 47690
A26: Bruno | B26: 49213.9
A27: Total Geral | B27: 207441.1
A37: Categoria | B37: % referente | C37: % restante | D37: Valor
A38: Calçado | B38: =D38/$D$41 -> 0.19696868 | C38: =$B$41-B38 -> 0.80303132 | D38: =SUMIF(Vendas[Categoria],'TBDN_Vendas Histórico'!A38,Vendas[Total]) -> 40859.4
A39: Vestuário | B39: =D39/$D$41 -> 0.65129427 | C39: =$B$41-B39 -> 0.34870573 | D39: =SUMIF(Vendas[Categoria],'TBDN_Vendas Histórico'!A39,Vendas[Total]) -> 135105.2
A40: Acessórios | B40: =D40/$D$41 -> 0.15173705 | C40: =$B$41-B40 -> 0.84826295 | D40: =SUMIF(Vendas[Categoria],'TBDN_Vendas Histórico'!A40,Vendas[Total]) -> 31476.5
A41: Total | B41: =SUM(B38:B40) -> 1 | D41: =SUM(D38:D40) -> 207441.1
